Workbook

Sheet Raw_Data
A1: YEAR | B1: MINERAL | C1: PROD. QTY (Tonnes) | D1: EXPORT VOL. (Tonnes) | E1: GLOBAL DEMAND base on World Prod. (Tonnes)
A2: 2023 | B2: Barite | C2: 30 | D2: 0 | E2: 7900000
A3: 2023 | B3: Beryl | C3: 978 | D3: 189 | E3: 8234
A4: 2023 | B4: Coal | C4: 481691.9 | D4: 154260 | E4: 9096000000
A5: 2023 | B5: Columbite | C5: 1860.46 | D5: 1128 | E5: NA
A6: 2023 | B6: Copper | C6: 0 | D6: 25 | E6: 23000000
A7: 2023 | B7: Feldspar | C7: 76575.16 | D7: 0 | E7: 32300000
A8: 2023 | B8: Gold | C8: 2.7 | D8: 1.68 | E8: 3300
A9: 2023 | B9: Gypsum | C9: 45235.18 | D9: 1000 | E9: 169700000
A10: 2023 | B10: Iron Ore | C10: 8896 | D10: 3500 | E10: 2507000000
A11: 2023 | B11: Kaolin | C11: 3000 | D11: 0 | E11: 28600000
A12: 2023 | B12: Lead/Zinc Ore | C12: 145803 | D12: 58920 | E12: 16100000
A13: 2023 | B13: Limestone | C13: 49057064 | D13: 20000 | E13: NA
A14: 2023 | B14: Lithium | C14: 78317.29 | D14: 35887 | E14: 209800
A15: 2023 | B15: Manganese | C15: 3600 | D15: 36000 | E15: 53000000
A16: 2023 | B16: Mica | C16: 145 | D16: 5218 | E16: 302000
A17: 2023 | B17: Talc | C17: 64400 | D17: 306 | E17: 7600000
A18: 2023 | B18: Tantalite | C18: 5.39 | D18: 65 | E18: 1600
A19: 2023 | B19: Tin Ore | C19: 4642.75 | D19: 3921 | E19: 29100
A20: 2022 | B20: Barite | C20: 1170 | D20: 0 | E20: 7900000
A21: 2022 | B21: Beryl | C21: 349 | D21: 0 | E21: 7721
A22: 2022 | B22: Coal | C22: 1505197 | D22: 122000 | E22: 8815000000
A23: 2022 | B23: Columbite | C23: 5899 | D23: 43382.33 | E23: NA
A24: 2022 | B24: Copper | C24: 82 | D24: 71.5 | E24: 22200000
A25: 2022 | B25: Feldspar | C25: 37250 | D25: 3658 | E25: 38100000
A26: 2022 | B26: Gold | C26: 2.9 | D26: 2.64 | E26: 3300
A27: 2022 | B27: Gypsum | C27: 183628 | D27: 0 | E27: 168500000
A28: 2022 | B28: Iron Ore | C28: 283 | D28: 0 | E28: 2436000000
A29: 2022 | B29: Kaolin | C29: 70396 | D29: 0 | E29: 31400000
A30: 2022 | B30: Lead/Zinc Ore | C30: 89130 | D30: 72725 | E30: 17400000
A31: 2022 | B31: Limestone | C31: 37260778 | D31: 0 | E31: NA
A32: 2022 | B32: Lithium | C32: 51524 | D32: 25916.4 | E32: 161700
A33: 2022 | B33: Manganese | C33: 56014 | D33: 15000 | E33: 54600000
A34: 2022 | B34: Mica | C34: 15 | D34: 1288 | E34: 274000
A35: 2022 | B35: Talc | C35: 65000 | D35: 50 | E35: 6900000
A36: 2022 | B36: Tantalite | C36: 4 | D36: 39 | E36: 1400
A37: 2022 | B37: Tin Ore | C37: 1705 | D37: 9405.58 | E37: 28700

Sheet KPIs
A1: Year | B1: Minerals | C1: YoY_Prod_% | D1: YoY_Export_% | E1: YoY_Global_Demand_% | F1: Export_Intensity | G1: Export_Intensity_Category | H1: Global_Share | I1: Global_Share_Category
A2: 2023 | B2: Barite | C2: =IFERROR(((Raw_Data!C2-Raw_Data!C20)/Raw_Data!C20),"NA") -> -0.97435897 | D2: =IFERROR(((Raw_Data!D2-Raw_Data!D20)/Raw_Data!D20),"NA") -> NA | E2: =IFERROR(((Raw_Data!E2-Raw_Data!E20)/Raw_Data!E20),"NA") -> 0 | F2: =IFERROR((Raw_Data!D2/Raw_Data!C2),"NA") -> 0 | G2: =IF(F2=0, "No Export", IF(F2<0.25, "Low", IF(F2<0.75, "Medium", IF(F2<=1, "High", IF(F2="NA", "NA", "Above Unity"))))) -> No Export | H2: =IFERROR((Raw_Data!C2/Raw_Data!E2),"NA") -> 3.7974684e-06 | I2: =IF(H2<0.0001, "Negligible", IF(H2<0.001, "Low", IF(H2<0.01, "Moderate", IF(H2>="NA", "NA", "Significant")))) -> Negligible
A3: 2023 | B3: Beryl | C3: =IFERROR(((Raw_Data!C3-Raw_Data!C21)/Raw_Data!C21),"NA") -> 1.8022923 | D3: =IFERROR(((Raw_Data!D3-Raw_Data!D21)/Raw_Data!D21),"NA") -> NA | E3: =IFERROR(((Raw_Data!E3-Raw_Data!E21)/Raw_Data!E21),"NA") -> 0.066442171 | F3: =IFERROR((Raw_Data!D3/Raw_Data!C3),"NA") -> 0.19325153 | G3: =IF(F3=0, "No Export", IF(F3<0.25, "Low", IF(F3<0.75, "Medium", IF(F3<=1, "High", IF(F3="NA", "NA", "Above Unity"))))) -> Low | H3: =IFERROR((Raw_Data!C3/Raw_Data!E3),"NA") -> 0.11877581 | I3: =IF(H3<0.0001, "Negligible", IF(H3<0.001, "Low", IF(H3<0.01, "Moderate", IF(H3>="NA", "NA", "Significant")))) -> Significant
A4: 2023 | B4: Coal | C4: =IFERROR(((Raw_Data!C4-Raw_Data!C22)/Raw_Data!C22),"NA") -> -0.67998083 | D4: =IFERROR(((Raw_Data!D4-Raw_Data!D22)/Raw_Data!D22),"NA") -> 0.26442623 | E4: =IFERROR(((Raw_Data!E4-Raw_Data!E22)/Raw_Data!E22),"NA") -> 0.031877482 | F4: =IFERROR((Raw_Data!D4/Raw_Data!C4),"NA") -> 0.3202462 | G4: =IF(F4=0, "No Export", IF(F4<0.25, "Low", IF(F4<0.75, "Medium", IF(F4<=1, "High", IF(F4="NA", "NA", "Above Unity"))))) -> Medium | H4: =IFERROR((Raw_Data!C4/Raw_Data!E4),"NA") -> 5.2956453e-05 | I4: =IF(H4<0.0001, "Negligible", IF(H4<0.001, "Low", IF(H4<0.01, "Moderate", IF(H4>="NA", "NA", "Significant")))) -> Negligible
A5: 2023 | B5: Columbite | C5: =IFERROR(((Raw_Data!C5-Raw_Data!C23)/Raw_Data!C23),"NA") -> -0.68461434 | D5: =IFERROR(((Raw_Data!D5-Raw_Data!D23)/Raw_Data!D23),"NA") -> -0.97399863 | E5: =IFERROR(((Raw_Data!E5-Raw_Data!E23)/Raw_Data!E23),"NA") -> NA | F5: =IFERROR((Raw_Data!D5/Raw_Data!C5),"NA") -> 0.60630167 | G5: =IF(F5=0, "No Export", IF(F5<0.25, "Low", IF(F5<0.75, "Medium", IF(F5<=1, "High", IF(F5="NA", "NA", "Above Unity"))))) -> Medium | H5: =IFERROR((Raw_Data!C5/Raw_Data!E5),"NA") -> NA | I5: =IF(H5<0.0001, "Negligible", IF(H5<0.001, "Low", IF(H5<0.01, "Moderate", IF(H5>="NA", "NA", "Significant")))) -> NA
A6: 2023 | B6: Copper | C6: =IFERROR(((Raw_Data!C6-Raw_Data!C24)/Raw_Data!C24),"NA") -> -1 | D6: =IFERROR(((Raw_Data!D6-Raw_Data!D24)/Raw_Data!D24),"NA") -> -0.65034965 | E6: =IFERROR(((Raw_Data!E6-Raw_Data!E24)/Raw_Data!E24),"NA") -> 0.036036036 | F6: =IFERROR((Raw_Data!D6/Raw_Data!C6),"NA") -> NA | G6: =IF(F6=0, "No Export", IF(F6<0.25, "Low", IF(F6<0.75, "Medium", IF(F6<=1, "High", IF(F6="NA", "NA", "Above Unity"))))) -> NA | H6: =IFERROR((Raw_Data!C6/Raw_Data!E6),"NA") -> 0 | I6: =IF(H6<0.0001, "Negligible", IF(H6<0.001, "Low", IF(H6<0.01, "Moderate", IF(H6>="NA", "NA", "Significant")))) -> Negligible
A7: 2023 | B7: Feldspar | C7: =IFERROR(((Raw_Data!C7-Raw_Data!C25)/Raw_Data!C25),"NA") -> 1.055709 | D7: =IFERROR(((Raw_Data!D7-Raw_Data!D25)/Raw_Data!D25),"NA") -> -1 | E7: =IFERROR(((Raw_Data!E7-Raw_Data!E25)/Raw_Data!E25),"NA") -> -0.15223097 | F7: =IFERROR((Raw_Data!D7/Raw_Data!C7),"NA") -> 0 | G7: =IF(F7=0, "No Export", IF(F7<0.25, "Low", IF(F7<0.75, "Medium", IF(F7<=1, "High", IF(F7="NA", "NA", "Above Unity"))))) -> No Export | H7: =IFERROR((Raw_Data!C7/Raw_Data!E7),"NA") -> 0.002370748 | I7: =IF(H7<0.0001, "Negligible", IF(H7<0.001, "Low", IF(H7<0.01, "Moderate", IF(H7>="NA", "NA", "Significant")))) -> Moderate
A8: 2023 | B8: Gold | C8: =IFERROR(((Raw_Data!C8-Raw_Data!C26)/Raw_Data!C26),"NA") -> -0.068965517 | D8: =IFERROR(((Raw_Data!D8-Raw_Data!D26)/Raw_Data!D26),"NA") -> -0.36363636 | E8: =IFERROR(((Raw_Data!E8-Raw_Data!E26)/Raw_Data!E26),"NA") -> 0 | F8: =IFERROR((Raw_Data!D8/Raw_Data!C8),"NA") -> 0.62222222 | G8: =IF(F8=0, "No Export", IF(F8<0.25, "Low", IF(F8<0.75, "Medium", IF(F8<=1, "High", IF(F8="NA", "NA", "Above Unity"))))) -> Medium | H8: =IFERROR((Raw_Data!C8/Raw_Data!E8),"NA") -> 0.00081818182 | I8: =IF(H8<0.0001, "Negligible", IF(H8<0.001, "Low", IF(H8<0.01, "Moderate", IF(H8>="NA", "NA", "Significant")))) -> Low
A9: 2023 | B9: Gypsum | C9: =IFERROR(((Raw_Data!C9-Raw_Data!C27)/Raw_Data!C27),"NA") -> -0.75365859 | D9: =IFERROR(((Raw_Data!D9-Raw_Data!D27)/Raw_Data!D27),"NA") -> NA | E9: =IFERROR(((Raw_Data!E9-Raw_Data!E27)/Raw_Data!E27),"NA") -> 0.0071216617 | F9: =IFERROR((Raw_Data!D9/Raw_Data!C9),"NA") -> 0.022106688 | G9: =IF(F9=0, "No Export", IF(F9<0.25, "Low", IF(F9<0.75, "Medium", IF(F9<=1, "High", IF(F9="NA", "NA", "Above Unity"))))) -> Low | H9: =IFERROR((Raw_Data!C9/Raw_Data!E9),"NA") -> 0.00026655969 | I9: =IF(H9<0.0001, "Negligible", IF(H9<0.001, "Low", IF(H9<0.01, "Moderate", IF(H9>="NA", "NA", "Significant")))) -> Low
A10: 2023 | B10: Iron Ore | C10: =IFERROR(((Raw_Data!C10-Raw_Data!C28)/Raw_Data!C28),"NA") -> 30.434629 | D10: =IFERROR(((Raw_Data!D10-Raw_Data!D28)/Raw_Data!D28),"NA") -> NA | E10: =IFERROR(((Raw_Data!E10-Raw_Data!E28)/Raw_Data!E28),"NA") -> 0.029146141 | F10: =IFERROR((Raw_Data!D10/Raw_Data!C10),"NA") -> 0.39343525 | G10: =IF(F10=0, "No Export", IF(F10<0.25, "Low", IF(F10<0.75, "Medium", IF(F10<=1, "High", IF(F10="NA", "NA", "Above Unity"))))) -> Medium | H10: =IFERROR((Raw_Data!C10/Raw_Data!E10),"NA") -> 3.5484643e-06 | I10: =IF(H10<0.0001, "Negligible", IF(H10<0.001, "Low", IF(H10<0.01, "Moderate", IF(H10>="NA", "NA", "Significant")))) -> Negligible
A11: 2023 | B11: Kaolin | C11: =IFERROR(((Raw_Data!C11-Raw_Data!C29)/Raw_Data!C29),"NA") -> -0.95738394 | D11: =IFERROR(((Raw_Data!D11-Raw_Data!D29)/Raw_Data!D29),"NA") -> NA | E11: =IFERROR(((Raw_Data!E11-Raw_Data!E29)/Raw_Data!E29),"NA") -> -0.089171975 | F11: =IFERROR((Raw_Data!D11/Raw_Data!C11),"NA") -> 0 | G11: =IF(F11=0, "No Export", IF(F11<0.25, "Low", IF(F11<0.75, "Medium", IF(F11<=1, "High", IF(F11="NA", "NA", "Above Unity"))))) -> No Export | H11: =IFERROR((Raw_Data!C11/Raw_Data!E11),"NA") -> 0.0001048951 | I11: =IF(H11<0.0001, "Negligible", IF(H11<0.001, "Low", IF(H11<0.01, "Moderate", IF(H11>="NA", "NA", "Significant")))) -> Low
A12: 2023 | B12: Lead/Zinc Ore | C12: =IFERROR(((Raw_Data!C12-Raw_Data!C30)/Raw_Data!C30),"NA") -> 0.63584652 | D12: =IFERROR(((Raw_Data!D12-Raw_Data!D30)/Raw_Data!D30),"NA") -> -0.18982468 | E12: =IFERROR(((Raw_Data!E12-Raw_Data!E30)/Raw_Data!E30),"NA") -> -0.074712644 | F12: =IFERROR((Raw_Data!D12/Raw_Data!C12),"NA") -> 0.40410691 | G12: =IF(F12=0, "No Export", IF(F12<0.25, "Low", IF(F12<0.75, "Medium", IF(F12<=1, "High", IF(F12="NA", "NA", "Above Unity"))))) -> Medium | H12: =IFERROR((Raw_Data!C12/Raw_Data!E12),"NA") -> 0.009056087 | I12: =IF(H12<0.0001, "Negligible", IF(H12<0.001, "Low", IF(H12<0.01, "Moderate", IF(H12>="NA", "NA", "Significant")))) -> Moderate
A13: 2023 | B13: Limestone | C13: =IFERROR(((Raw_Data!C13-Raw_Data!C31)/Raw_Data!C31),"NA") -> 0.31658722 | D13: =IFERROR(((Raw_Data!D13-Raw_Data!D31)/Raw_Data!D31),"NA") -> NA | E13: =IFERROR(((Raw_Data!E13-Raw_Data!E31)/Raw_Data!E31),"NA") -> NA | F13: =IFERROR((Raw_Data!D13/Raw_Data!C13),"NA") -> 0.00040768848 | G13: =IF(F13=0, "No Export", IF(F13<0.25, "Low", IF(F13<0.75, "Medium", IF(F13<=1, "High", IF(F13="NA", "NA", "Above Unity"))))) -> Low | H13: =IFERROR((Raw_Data!C13/Raw_Data!E13),"NA") -> NA | I13: =IF(H13<0.0001, "Negligible", IF(H13<0.001, "Low", IF(H13<0.01, "Moderate", IF(H13>="NA", "NA", "Significant")))) -> NA
... A37: 2022 | B37: Tin Ore | C37: =IFERROR(((Raw_Data!C37-Raw_Data!C55)/Raw_Data!C55),"NA") -> NA | D37: =IFERROR(((Raw_Data!D37-Raw_Data!D55)/Raw_Data!D55),"NA") -> NA | E37: =IFERROR(((Raw_Data!E37-Raw_Data!E55)/Raw_Data!E55),"NA") -> NA | F37: =IFERROR((Raw_Data!D37/Raw_Data!C37),"NA") -> 5.5164692 | G37: =IF(F37=0, "No Export", IF(F37<0.25, "Low", IF(F37<0.75, "Medium", IF(F37<=1, "High", IF(F37="NA", "NA", "Above Unity"))))) -> Above Unity | H37: =IFERROR((Raw_Data!C37/Raw_Data!E37),"NA") -> 0.059407666 | I37: =IF(H37<0.0001, "Negligible", IF(H37<0.001, "Low", IF(H37<0.01, "Moderate", IF(H37>="NA", "NA", "Significant")))) -> Significant

Sheet KPIs_Copy
A1: Minerals | B1: YoY_Prod_%
A2: Copper | B2: -1
A3: Barite | B3: -0.97435897
A4: Kaolin | B4: -0.95738394
A5: Manganese | B5: -0.93573035
A6: Gypsum | B6: -0.75365859
A7: Columbite | B7: -0.68461434
A8: Coal | B8: -0.67998083
A9: Gold | B9: -0.068965517
A10: Talc | B10: -0.0092307692
A11: Limestone | B11: 0.31658722
A12: Tantalite | B12: 0.3475
A13: Lithium | B13: 0.52001572
... A19: Iron Ore | B19: 30.434629
A22: Minerals | B22: YoY_Export_%
A23: Feldspar | B23: -1
A24: Columbite | B24: -0.97399863
A25: Copper | B25: -0.65034965
A26: Tin Ore | B26: -0.58311981
A27: Gold | B27: -0.36363636
A28: Lead/Zinc Ore | B28: -0.18982468
A29: Coal | B29: 0.26442623
A30: Lithium | B30: 0.38472164
A31: Tantalite | B31: 0.66666667
A32: Manganese | B32: 1.4
A33: Mica | B33: 3.0512422
A34: Talc | B34: 5.12
A35: Barite | B35: NA
A36: Beryl | B36: NA
A37: Gypsum | B37: NA
A38: Iron Ore | B38: NA
A39: Kaolin | B39: NA
A40: Limestone | B40: NA
A43: Minerals | B43: YoY_Global_Demand_%
A44: Feldspar | B44: -0.15223097
A45: Kaolin | B45: -0.089171975
A46: Lead/Zinc Ore | B46: -0.074712644
A47: Manganese | B47: -0.029304029
A48: Barite | B48: 0
A49: Gold | B49: 0
...
